Workbook

Sheet Hesaplar
J1: Tüm Türkiye | M1: ilgili bölgeler
J2: Maks erişim | K2: 0.25 | M2: Maks erişim | N2: 0.7
B3: Ünite | C3: İl | D3: Günlük Gösterim | E3: Kullanım Süresi | F3: Adet | G3: Toplam Gösterim | H3: Frekans | I3: Erişim (Kişi) | J3: Hedeflenen Evren | K3: Erişim (%) | L3: GRP | M3: Hedeflenen Evren | N3: Erişim (%) | O3: GRP
B4: Durak Raket CLP | C4: İstanbul | D4: =SUMIFS('Günlük Gösterim Sayıları'!D:D, 'Günlük Gösterim Sayıları'!B:B, C4, 'Günlük Gösterim Sayıları'!C:C, B4) -> 17412 | E4: =_xlfn.XLOOKUP(B4, 'Günlük Gösterim Sayıları'!O:O, 'Günlük Gösterim Sayıları'!P:P, 7) -> 1 | F4: 400 | G4: =+D4*E4*F4 -> 6964800 | H4: =SUMIFS('Günlük Gösterim Sayıları'!E:E, 'Günlük Gösterim Sayıları'!B:B, C4, 'Günlük Gösterim Sayıları'!C:C, B4) -> 17 | I4: =IF(H4=0, 0, G4/H4) -> 409694.12 | J4: =+'Günlük Gösterim Sayıları'!P8 -> 86920168 | K4: =I4/J4 -> 0.0047134529 | L4: =+G4/J4*100 -> 8.0128699 | M4: =_xlfn.XLOOKUP(C4, 'Günlük Gösterim Sayıları'!O:O, 'Günlük Gösterim Sayıları'!P:P, 86920168) -> 15754053 | N4: =+I4/M4 -> 0.026005633 | O4: =+G4/M4*100 -> 44.209576
B5: Billboard | C5: Ankara | D5: =SUMIFS('Günlük Gösterim Sayıları'!D:D, 'Günlük Gösterim Sayıları'!B:B, C5, 'Günlük Gösterim Sayıları'!C:C, B5) -> 56529.372 | E5: =_xlfn.XLOOKUP(B5, 'Günlük Gösterim Sayıları'!O:O, 'Günlük Gösterim Sayıları'!P:P, 7) -> 1 | F5: 200 | G5: =+D5*E5*F5 -> 11305874 | H5: =SUMIFS('Günlük Gösterim Sayıları'!E:E, 'Günlük Gösterim Sayıları'!B:B, C5, 'Günlük Gösterim Sayıları'!C:C, B5) -> 15.301 | I5: =IF(H5=0, 0, G5/H5) -> 738897.75 | J5: =+'Günlük Gösterim Sayıları'!P8 -> 86920168 | K5: =I5/J5 -> 0.008500878 | L5: =+G5/J5*100 -> 13.007193 | M5: =_xlfn.XLOOKUP(C5, 'Günlük Gösterim Sayıları'!O:O, 'Günlük Gösterim Sayıları'!P:P, 86920168) -> 5910320 | N5: =+I5/M5 -> 0.12501823 | O5: =+G5/M5*100 -> 191.29039
B6: Üst Geçit Alınlık | C6: İstanbul | D6: =SUMIFS('Günlük Gösterim Sayıları'!D:D, 'Günlük Gösterim Sayıları'!B:B, C6, 'Günlük Gösterim Sayıları'!C:C, B6) -> 150000 | E6: =_xlfn.XLOOKUP(B6, 'Günlük Gösterim Sayıları'!O:O, 'Günlük Gösterim Sayıları'!P:P, 7) -> 1 | F6: 5 | G6: =+D6*E6*F6 -> 750000 | H6: =SUMIFS('Günlük Gösterim Sayıları'!E:E, 'Günlük Gösterim Sayıları'!B:B, C6, 'Günlük Gösterim Sayıları'!C:C, B6) -> 4 | I6: =IF(H6=0, 0, G6/H6) -> 187500 | J6: =+'Günlük Gösterim Sayıları'!P8 -> 86920168 | K6: =I6/J6 -> 0.0021571518 | L6: =+G6/J6*100 -> 0.86286073 | M6: =_xlfn.XLOOKUP(C6, 'Günlük Gösterim Sayıları'!O:O, 'Günlük Gösterim Sayıları'!P:P, 86920168) -> 15754053 | N6: =+I6/M6 -> 0.011901699 | O6: =+G6/M6*100 -> 4.7606797
B7: Giantboard | C7: İstanbul | D7: =SUMIFS('Günlük Gösterim Sayıları'!D:D, 'Günlük Gösterim Sayıları'!B:B, C7, 'Günlük Gösterim Sayıları'!C:C, B7) -> 100000 | E7: =_xlfn.XLOOKUP(B7, 'Günlük Gösterim Sayıları'!O:O, 'Günlük Gösterim Sayıları'!P:P, 7) -> 1 | F7: 10 | G7: =+D7*E7*F7 -> 1000000 | H7: =SUMIFS('Günlük Gösterim Sayıları'!E:E, 'Günlük Gösterim Sayıları'!B:B, C7, 'Günlük Gösterim Sayıları'!C:C, B7) -> 3.4 | I7: =IF(H7=0, 0, G7/H7) -> 294117.65 | J7: =+'Günlük Gösterim Sayıları'!P8 -> 86920168 | K7: =I7/J7 -> 0.0033837676 | L7: =+G7/J7*100 -> 1.150481 | M7: =_xlfn.XLOOKUP(C7, 'Günlük Gösterim Sayıları'!O:O, 'Günlük Gösterim Sayıları'!P:P, 86920168) -> 15754053 | N7: =+I7/M7 -> 0.018669332 | O7: =+G7/M7*100 -> 6.3475729
B8: Durak Raket CLP | C8: Ankara
K10: =L10*K2*100/(L10+K2*100)/100 -> 0.11988222 | L10: =SUM(L4:L7) -> 23.033405 | N10: =O10*N2*100/(O10+N2*100)/100 -> 0.54523459 | O10: =SUM(O4:O7) -> 246.60822

Sheet Otomatik Hesaplama
B1: OTOMATİK HESAPLAMA | J1: Tüm Türkiye | M1: ilgili bölgeler
J2: Maks erişim | K2: {=IFERROR((SUMPRODUCT((M4:M13) / IF(COUNTIF(C4:C13, C4:C13&"")=0, 1, COUNTIF(C4:C13, C4:C13&"")) * (C4:C13<>"")) / 86092168) * 100, 0)} -> 0 | M2: Maks erişim | N2: 0.7
B3: Ünite | C3: İl | D3: Günlük Gösterim | E3: Kullanım Süresi | F3: Adet | G3: Toplam Gösterim | H3: Frekans | I3: Erişim (Kişi) | J3: Hedeflenen Evren | K3: Erişim (%) | L3: GRP | M3: Hedeflenen Evren | N3: Erişim (%) | O3: GRP
D4: =SUMIFS('Günlük Gösterim Sayıları'!D:D, 'Günlük Gösterim Sayıları'!B:B, C4, 'Günlük Gösterim Sayıları'!C:C, B4) -> 0 | E4: =_xlfn.XLOOKUP(B4, 'Günlük Gösterim Sayıları'!O:O, 'Günlük Gösterim Sayıları'!P:P, 7) -> 0 | G4: =+D4*E4*F4 -> 0 | H4: =SUMIFS('Günlük Gösterim Sayıları'!E:E, 'Günlük Gösterim Sayıları'!B:B, C4, 'Günlük Gösterim Sayıları'!C:C, B4) -> 0 | I4: =IF(H4=0, 0, G4/H4) -> 0 | J4: =+'Günlük Gösterim Sayıları'!$P$8 -> 86920168 | K4: =I4/J4 -> 0 | L4: =+G4/J4*100 -> 0 | M4: =IFERROR(VLOOKUP(C4, 'Günlük Gösterim Sayıları'!B:P, 9, FALSE), 0) -> 0 | N4: =+I4/M4 -> #DIV/0! | O4: =+G4/M4*100 -> #DIV/0!
D5: =SUMIFS('Günlük Gösterim Sayıları'!D:D, 'Günlük Gösterim Sayıları'!B:B, C5, 'Günlük Gösterim Sayıları'!C:C, B5) -> 0 | E5: =_xlfn.XLOOKUP(B5, 'Günlük Gösterim Sayıları'!O:O, 'Günlük Gösterim Sayıları'!P:P, 7) -> 0 | G5: =+D5*E5*F5 -> 0 | H5: =SUMIFS('Günlük Gösterim Sayıları'!E:E, 'Günlük Gösterim Sayıları'!B:B, C5, 'Günlük Gösterim Sayıları'!C:C, B5) -> 0 | I5: =IF(H5=0, 0, G5/H5) -> 0 | J5: =+'Günlük Gösterim Sayıları'!P8 -> 86920168 | K5: =I5/J5 -> 0 | L5: =+G5/J5*100 -> 0 | M5: =_xlfn.XLOOKUP(C5, 'Günlük Gösterim Sayıları'!O:O, 'Günlük Gösterim Sayıları'!P:P, 86920168) -> 0 | N5: =+I5/M5 -> #DIV/0! | O5: =+G5/M5*100 -> #DIV/0!
D6: =SUMIFS('Günlük Gösterim Sayıları'!D:D, 'Günlük Gösterim Sayıları'!B:B, C6, 'Günlük Gösterim Sayıları'!C:C, B6) -> 0 | E6: =_xlfn.XLOOKUP(B6, 'Günlük Gösterim Sayıları'!O:O, 'Günlük Gösterim Sayıları'!P:P, 7) -> 0 | G6: =+D6*E6*F6 -> 0 | H6: =SUMIFS('Günlük Gösterim Sayıları'!E:E, 'Günlük Gösterim Sayıları'!B:B, C6, 'Günlük Gösterim Sayıları'!C:C, B6) -> 0 | I6: =IF(H6=0, 0, G6/H6) -> 0 | J6: =+'Günlük Gösterim Sayıları'!$P$8 -> 86920168 | K6: =I6/J6 -> 0 | L6: =+G6/J6*100 -> 0 | M6: =_xlfn.XLOOKUP(C6, 'Günlük Gösterim Sayıları'!O:O, 'Günlük Gösterim Sayıları'!P:P, 86920168) -> 0 | N6: =+I6/M6 -> #DIV/0! | O6: =+G6/M6*100 -> #DIV/0!
D7: =SUMIFS('Günlük Gösterim Sayıları'!D:D, 'Günlük Gösterim Sayıları'!B:B, C7, 'Günlük Gösterim Sayıları'!C:C, B7) -> 0 | E7: =_xlfn.XLOOKUP(B7, 'Günlük Gösterim Sayıları'!O:O, 'Günlük Gösterim Sayıları'!P:P, 7) -> 0 | G7: =+D7*E7*F7 -> 0 | H7: =SUMIFS('Günlük Gösterim Sayıları'!E:E, 'Günlük Gösterim Sayıları'!B:B, C7, 'Günlük Gösterim Sayıları'!C:C, B7) -> 0 | I7: =IF(H7=0, 0, G7/H7) -> 0 | J7: =+'Günlük Gösterim Sayıları'!$P$8 -> 86920168 | K7: =I7/J7 -> 0 | L7: =+G7/J7*100 -> 0 | M7: =_xlfn.XLOOKUP(C7, 'Günlük Gösterim Sayıları'!O:O, 'Günlük Gösterim Sayıları'!P:P, 86920168) -> 0 | N7: =+I7/M7 -> #DIV/0! | O7: =+G7/M7*100 -> #DIV/0!
D8: =SUMIFS('Günlük Gösterim Sayıları'!D:D, 'Günlük Gösterim Sayıları'!B:B, C8, 'Günlük Gösterim Sayıları'!C:C, B8) -> 0 | E8: =_xlfn.XLOOKUP(B8, 'Günlük Gösterim Sayıları'!O:O, 'Günlük Gösterim Sayıları'!P:P, 7) -> 0 | G8: =+D8*E8*F8 -> 0 | H8: =SUMIFS('Günlük Gösterim Sayıları'!E:E, 'Günlük Gösterim Sayıları'!B:B, C8, 'Günlük Gösterim Sayıları'!C:C, B8) -> 0 | I8: =IF(H8=0, 0, G8/H8) -> 0 | J8: =+'Günlük Gösterim Sayıları'!$P$8 -> 86920168 | K8: =I8/J8 -> 0 | L8: =+G8/J8*100 -> 0 | M8: =_xlfn.XLOOKUP(C8, 'Günlük Gösterim Sayıları'!O:O, 'Günlük Gösterim Sayıları'!P:P, 86920168) -> 0 | N8: =+I8/M8 -> #DIV/0! | O8: =+G8/M8*100 -> #DIV/0!
D9: =SUMIFS('Günlük Gösterim Sayıları'!D:D, 'Günlük Gösterim Sayıları'!B:B, C9, 'Günlük Gösterim Sayıları'!C:C, B9) -> 0 | E9: =_xlfn.XLOOKUP(B9, 'Günlük Gösterim Sayıları'!O:O, 'Günlük Gösterim Sayıları'!P:P, 7) -> 0 | G9: =+D9*E9*F9 -> 0 | H9: =SUMIFS('Günlük Gösterim Sayıları'!E:E, 'Günlük Gösterim Sayıları'!B:B, C9, 'Günlük Gösterim Sayıları'!C:C, B9) -> 0 | I9: =IF(H9=0, 0, G9/H9) -> 0 | J9: =+'Günlük Gösterim Sayıları'!$P$8 -> 86920168 | K9: =I9/J9 -> 0 | L9: =+G9/J9*100 -> 0 | M9: =_xlfn.XLOOKUP(C9, 'Günlük Gösterim Sayıları'!O:O, 'Günlük Gösterim Sayıları'!P:P, 86920168) -> 0 | N9: =+I9/M9 -> #DIV/0! | O9: =+G9/M9*100 -> #DIV/0!
D10: =SUMIFS('Günlük Gösterim Sayıları'!D:D, 'Günlük Gösterim Sayıları'!B:B, C10, 'Günlük Gösterim Sayıları'!C:C, B10) -> 0 | E10: =_xlfn.XLOOKUP(B10, 'Günlük Gösterim Sayıları'!O:O, 'Günlük Gösterim Sayıları'!P:P, 7) -> 0 | G10: =+D10*E10*F10 -> 0 | H10: =SUMIFS('Günlük Gösterim Sayıları'!E:E, 'Günlük Gösterim Sayıları'!B:B, C10, 'Günlük Gösterim Sayıları'!C:C, B10) -> 0 | I10: =IF(H10=0, 0, G10/H10) -> 0 | J10: =+'Günlük Gösterim Sayıları'!$P$8 -> 86920168 | K10: =I10/J10 -> 0 | L10: =+G10/J10*100 -> 0 | M10: =_xlfn.XLOOKUP(C10, 'Günlük Gösterim Sayıları'!O:O, 'Günlük Gösterim Sayıları'!P:P, 86920168) -> 0 | N10: =+I10/M10 -> #DIV/0! | O10: =+G10/M10*100 -> #DIV/0!
D11: =SUMIFS('Günlük Gösterim Sayıları'!D:D, 'Günlük Gösterim Sayıları'!B:B, C11, 'Günlük Gösterim Sayıları'!C:C, B11) -> 0 | E11: =_xlfn.XLOOKUP(B11, 'Günlük Gösterim Sayıları'!O:O, 'Günlük Gösterim Sayıları'!P:P, 7) -> 0 | G11: =+D11*E11*F11 -> 0 | H11: =SUMIFS('Günlük Gösterim Sayıları'!E:E, 'Günlük Gösterim Sayıları'!B:B, C11, 'Günlük Gösterim Sayıları'!C:C, B11) -> 0 | I11: =IF(H11=0, 0, G11/H11) -> 0 | J11: =+'Günlük Gösterim Sayıları'!$P$8 -> 86920168 | K11: =I11/J11 -> 0 | L11: =+G11/J11*100 -> 0 | M11: =_xlfn.XLOOKUP(C11, 'Günlük Gösterim Sayıları'!O:O, 'Günlük Gösterim Sayıları'!P:P, 86920168) -> 0 | N11: =+I11/M11 -> #DIV/0! | O11: =+G11/M11*100 -> #DIV/0!
D12: =SUMIFS('Günlük Gösterim Sayıları'!D:D, 'Günlük Gösterim Sayıları'!B:B, C12, 'Günlük Gösterim Sayıları'!C:C, B12) -> 0 | E12: =_xlfn.XLOOKUP(B12, 'Günlük Gösterim Sayıları'!O:O, 'Günlük Gösterim Sayıları'!P:P, 7) -> 0 | G12: =+D12*E12*F12 -> 0 | H12: =SUMIFS('Günlük Gösterim Sayıları'!E:E, 'Günlük Gösterim Sayıları'!B:B, C12, 'Günlük Gösterim Sayıları'!C:C, B12) -> 0 | I12: =IF(H12=0, 0, G12/H12) -> 0 | J12: =+'Günlük Gösterim Sayıları'!$P$8 -> 86920168 | K12: =I12/J12 -> 0 | L12: =+G12/J12*100 -> 0 | M12: =_xlfn.XLOOKUP(C12, 'Günlük Gösterim Sayıları'!O:O, 'Günlük Gösterim Sayıları'!P:P, 86920168) -> 0 | N12: =+I12/M12 -> #DIV/0! | O12: =+G12/M12*100 -> #DIV/0!
D13: =SUMIFS('Günlük Gösterim Sayıları'!D:D, 'Günlük Gösterim Sayıları'!B:B, C13, 'Günlük Gösterim Sayıları'!C:C, B13) -> 0 | E13: =_xlfn.XLOOKUP(B13, 'Günlük Gösterim Sayıları'!O:O, 'Günlük Gösterim Sayıları'!P:P, 7) -> 0 | G13: =+D13*E13*F13 -> 0 | H13: =SUMIFS('Günlük Gösterim Sayıları'!E:E, 'Günlük Gösterim Sayıları'!B:B, C13, 'Günlük Gösterim Sayıları'!C:C, B13) -> 0 | I13: =IF(H13=0, 0, G13/H13) -> 0 | J13: =+'Günlük Gösterim Sayıları'!$P$8 -> 86920168 | K13: =I13/J13 -> 0 | L13: =+G13/J13*100 -> 0 | M13: =_xlfn.XLOOKUP(C13, 'Günlük Gösterim Sayıları'!O:O, 'Günlük Gösterim Sayıları'!P:P, 86920168) -> 0 | N13: =+I13/M13 -> #DIV/0! | O13: =+G13/M13*100 -> #DIV/0!
K16: =L16*K2*100/(L16+K2*100)/100 -> #DIV/0! | L16: =SUM(L4:L13) -> 0 | N16: =O16*N2*100/(O16+N2*100)/100 -> #DIV/0! | O16: =SUM(O4:O5) -> #DIV/0!

Sheet Kampanya
B1: OTOMATİK HESAPLAMA | M1: Tüm Türkiye | P1: ilgili bölgeler
M2: Maks erişim | N2: 0.25 | P2: Maks erişim | Q2: 0.7
B3: Ünite | C3: İl | D3: Marka | E3: Kampanya | F3: Bütçe | G3: Günlük Gösterim | H3: Kullanım Süresi | I3: Adet | J3: Toplam Gösterim | K3: Frekans | L3: Erişim (Kişi) | M3: Hedeflenen Evren | N3: Erişim (%) | O3: GRP | P3: Hedeflenen Evren | Q3: Erişim (%) | R3: GRP
B4: Durak Raket CLP | C4: İstanbul | D4: Burgan Bank | E4: 46023 | F4: 2500000 | G4: =SUMIFS('Günlük Gösterim Sayıları'!D:D, 'Günlük Gösterim Sayıları'!B:B, C4, 'Günlük Gösterim Sayıları'!C:C, B4) -> 17412 | H4: =_xlfn.XLOOKUP(B4, 'Günlük Gösterim Sayıları'!O:O, 'Günlük Gösterim Sayıları'!P:P, 7) -> 1 | I4: 400 | J4: =+G4*H4*I4 -> 6964800 | K4: =SUMIFS('Günlük Gösterim Sayıları'!E:E, 'Günlük Gösterim Sayıları'!B:B, C4, 'Günlük Gösterim Sayıları'!C:C, B4) -> 17 | L4: =IF(K4=0, 0, J4/K4) -> 409694.12 | M4: =+'Günlük Gösterim Sayıları'!$P$8 -> 86920168 | N4: =L4/M4 -> 0.0047134529 | O4: =+J4/M4*100 -> 8.0128699 | P4: =_xlfn.XLOOKUP(C4, 'Günlük Gösterim Sayıları'!O:O, 'Günlük Gösterim Sayıları'!P:P, 86920168) -> 15754053 | Q4: =+L4/P4 -> 0.026005633 | R4: =+J4/P4*100 -> 44.209576
B5: Durak Raket CLP | C5: Ankara | D5: Burgan Bank | E5: 46023 | F5: 1214200 | G5: =SUMIFS('Günlük Gösterim Sayıları'!D:D, 'Günlük Gösterim Sayıları'!B:B, C5, 'Günlük Gösterim Sayıları'!C:C, B5) -> 19621.821 | H5: =_xlfn.XLOOKUP(B5, 'Günlük Gösterim Sayıları'!O:O, 'Günlük Gösterim Sayıları'!P:P, 7) -> 1 | I5: 200 | J5: =+G5*H5*I5 -> 3924364.3 | K5: =SUMIFS('Günlük Gösterim Sayıları'!E:E, 'Günlük Gösterim Sayıları'!B:B, C5, 'Günlük Gösterim Sayıları'!C:C, B5) -> 19.89 | L5: =IF(K5=0, 0, J5/K5) -> 0 | M5: =+'Günlük Gösterim Sayıları'!P8 -> 86920168 | N5: =L5/M5 -> 0 | O5: =+J5/M5*100 -> 4.5149065 | P5: =_xlfn.XLOOKUP(C5, 'Günlük Gösterim Sayıları'!O:O, 'Günlük Gösterim Sayıları'!P:P, 86920168) -> 5910320 | Q5: =+L5/P5 -> 0 | R5: =+J5/P5*100 -> 66.398508
B6: Durak Raket CLP | C6: Bursa | D6: Burgan Bank | E6: 46023 | F6: 1023020 | G6: =SUMIFS('Günlük Gösterim Sayıları'!D:D, 'Günlük Gösterim Sayıları'!B:B, C6, 'Günlük Gösterim Sayıları'!C:C, B6) -> 10800.293 | H6: =_xlfn.XLOOKUP(B6, 'Günlük Gösterim Sayıları'!O:O, 'Günlük Gösterim Sayıları'!P:P, 7) -> 1 | I6: 100 | J6: =+G6*H6*I6 -> 1080029.3 | K6: =SUMIFS('Günlük Gösterim Sayıları'!E:E, 'Günlük Gösterim Sayıları'!B:B, C6, 'Günlük Gösterim Sayıları'!C:C, B6) -> 21.59 | L6: =IF(K6=0, 0, J6/K6) -> 0 | M6: =+'Günlük Gösterim Sayıları'!$P$8 -> 86920168 | N6: =L6/M6 -> 0 | O6: =+J6/M6*100 -> 1.2425532 | P6: =_xlfn.XLOOKUP(C6, 'Günlük Gösterim Sayıları'!O:O, 'Günlük Gösterim Sayıları'!P:P, 86920168) -> 3263011 | Q6: =+L6/P6 -> 0 | R6: =+J6/P6*100 -> 33.099163
B7: Durak Raket CLP | C7: Antalya | D7: Burgan Bank | E7: 46023 | F7: 2322000 | G7: =SUMIFS('Günlük Gösterim Sayıları'!D:D, 'Günlük Gösterim Sayıları'!B:B, C7, 'Günlük Gösterim Sayıları'!C:C, B7) -> 12424.171 | H7: =_xlfn.XLOOKUP(B7, 'Günlük Gösterim Sayıları'!O:O, 'Günlük Gösterim Sayıları'!P:P, 7) -> 1 | I7: 100 | J7: =+G7*H7*I7 -> 1242417.1 | K7: =SUMIFS('Günlük Gösterim Sayıları'!E:E, 'Günlük Gösterim Sayıları'!B:B, C7, 'Günlük Gösterim Sayıları'!C:C, B7) -> 23.46 | L7: =IF(K7=0, 0, J7/K7) -> 0 | M7: =+'Günlük Gösterim Sayıları'!$P$8 -> 86920168 | N7: =L7/M7 -> 0 | O7: =+J7/M7*100 -> 1.4293772 | P7: =_xlfn.XLOOKUP(C7, 'Günlük Gösterim Sayıları'!O:O, 'Günlük Gösterim Sayıları'!P:P, 86920168) -> 2777677 | Q7: =+L7/P7 -> 0 | R7: =+J7/P7*100 -> 44.728637
B8: Giantboard | C8: İstanbul | D8: Burgan Bank | E8: 46023 | F8: 1420000 | G8: =SUMIFS('Günlük Gösterim Sayıları'!D:D, 'Günlük Gösterim Sayıları'!B:B, C8, 'Günlük Gösterim Sayıları'!C:C, B8) -> 100000 | H8: =_xlfn.XLOOKUP(B8, 'Günlük Gösterim Sayıları'!O:O, 'Günlük Gösterim Sayıları'!P:P, 7) -> 1 | I8: 10 | J8: =+G8*H8*I8 -> 1000000 | K8: =SUMIFS('Günlük Gösterim Sayıları'!E:E, 'Günlük Gösterim Sayıları'!B:B, C8, 'Günlük Gösterim Sayıları'!C:C, B8) -> 3.4 | L8: =IF(K8=0, 0, J8/K8) -> 294117.65 | M8: =+'Günlük Gösterim Sayıları'!$P$8 -> 86920168 | N8: =L8/M8 -> 0.0033837676 | O8: =+J8/M8*100 -> 1.150481 | P8: =_xlfn.XLOOKUP(C8, 'Günlük Gösterim Sayıları'!O:O, 'Günlük Gösterim Sayıları'!P:P, 86920168) -> 15754053 | Q8: =+L8/P8 -> 0.018669332 | R8: =+J8/P8*100 -> 6.3475729
B9: Üst Geçit Alınlık | C9: İstanbul | D9: Burgan Bank | E9: 46023 | F9: 2424212 | G9: =SUMIFS('Günlük Gösterim Sayıları'!D:D, 'Günlük Gösterim Sayıları'!B:B, C9, 'Günlük Gösterim Sayıları'!C:C, B9) -> 150000 | H9: =_xlfn.XLOOKUP(B9, 'Günlük Gösterim Sayıları'!O:O, 'Günlük Gösterim Sayıları'!P:P, 7) -> 1 | I9: 5 | J9: =+G9*H9*I9 -> 750000 | K9: =SUMIFS('Günlük Gösterim Sayıları'!E:E, 'Günlük Gösterim Sayıları'!B:B, C9, 'Günlük Gösterim Sayıları'!C:C, B9) -> 4 | L9: =IF(K9=0, 0, J9/K9) -> 187500 | M9: =+'Günlük Gösterim Sayıları'!$P$8 -> 86920168 | N9: =L9/M9 -> 0.0021571518 | O9: =+J9/M9*100 -> 0.86286073 | P9: =_xlfn.XLOOKUP(C9, 'Günlük Gösterim Sayıları'!O:O, 'Günlük Gösterim Sayıları'!P:P, 86920168) -> 15754053 | Q9: =+L9/P9 -> 0.011901699 | R9: =+J9/P9*100 -> 4.7606797
N10: =O10*N2*100/(O10+N2*100)/100 -> 0.10194152 | O10: =SUM(O4:O9) -> 17.213049 | Q10: =R10*Q2*100/(R10+Q2*100)/100 -> 0.51821159 | R10: =SUM(R4:R9) -> 199.54414

Sheet Günlük Gösterim Sayıları
B2: İl | C2: Ünite | D2: Günlük Gösterim/Adet | E2: Frekans | F2: Network Adedi | G2: Endeks | H2: Dikkate Alınacak Adet | I2: Günlük Gösterim/Adet | J2: Periyod | K2: Frekans | O2: İl | P2: Nüfus
B3: İstanbul | C3: Durak Raket CLP | D3: 17412 | E3: 17 | F3: 400 | G3: 1 | H3: 0 | I3: =+D3*G3 -> 17412 | J3: 1 | K3: =E3 * (H3 / F3)^0.55 * G3 * (J3^0.8) -> 0 | O3: İstanbul | P3: 15754053 | Q3: =+P3/P8 -> 0.18124738
B4: Ankara | C4: Durak Raket CLP | D4: 19621.821 | E4: =+$E$4*M4 -> 19.89 | F4: 400 | G4: 1 | H4: 0 | I4: =+D4 -> 19621.821 | J4: 1 | K4: =E4 * (H4 / F4)^0.55 * G4 * (J4^0.8) -> 0 | M4: 1.17 | O4: Ankara | P4: 5910320 | Q4: =+P4/P8 -> 0.067997107
B5: İzmir | C5: Durak Raket CLP | D5: 16884.661 | E5: =+$E$4*M5 -> 20.57 | F5: 400 | G5: 1 | H5: 0 | I5: =+D5 -> 16884.661 | J5: 1 | K5: =E5 * (H5 / F5)^0.55 * G5 * (J5^0.8) -> 0 | M5: 1.21 | O5: İzmir | P5: 4504185 | Q5: =+P5/P8 -> 0.051819792
B6: Bursa | C6: Durak Raket CLP | D6: 10800.293 | E6: =+$E$4*M6 -> 21.59 | F6: 400 | G6: 1 | H6: 0 | I6: =+D6 -> 10800.293 | J6: 1 | K6: =E6 * (H6 / F6)^0.55 * G6 * (J6^0.8) -> 0 | M6: 1.27 | O6: Bursa | P6: 3263011 | Q6: =+P6/P8 -> 0.037540321
B7: Antalya | C7: Durak Raket CLP | D7: 12424.171 | E7: =+$E$4*M7 -> 23.46 | F7: 400 | G7: 1 | H7: 0 | I7: =+D7 -> 12424.171 | J7: 1 | K7: =E7 * (H7 / F7)^0.55 * G7 * (J7^0.8) -> 0 | M7: 1.38 | O7: Antalya | P7: 2777677 | Q7: =+P7/P8 -> 0.031956646
B8: Anadolu İlleri | C8: Durak Raket CLP | D8: 9000 | E8: =+$E$4*M8 -> 27.71 | F8: 400 | G8: 1 | H8: 0 | I8: =+D8 -> 9000 | J8: 1 | K8: =E8 * (H8 / F8)^0.55 * G8 * (J8^0.8) -> 0 | M8: 1.63 | O8: Türkiye | P8: 86920168
B9: İstanbul | C9: Billboard | D9: 50163 | E9: 13 | F9: 200 | G9: 1 | H9: 0 | I9: =+D9 -> 50163 | J9: 1 | K9: =E9 * (H9 / F9)^0.55 * G9 * (J9^0.8) -> 0
B10: Ankara | C10: Billboard | D10: 56529.372 | E10: =+E9*1.177 -> 15.301 | F10: 200 | G10: 1 | H10: 0 | I10: =+D10 -> 56529.372 | J10: 1 | K10: =E10 * (H10 / F10)^0.55 * G10 * (J10^0.8) -> 0
B11: İzmir | C11: Billboard | D11: 48643.767 | E11: =+E9*1.21 -> 15.73 | F11: 200 | G11: 1 | H11: 0 | I11: =+D11 -> 48643.767 | J11: 1 | K11: =E11 * (H11 / F11)^0.55 * G11 * (J11^0.8) -> 0
B12: Bursa | C12: Billboard | D12: 31115.042 | E12: =+E9*1.27 -> 16.51 | F12: 200 | G12: 1 | H12: 0 | I12: =+D12 -> 31115.042 | J12: 1 | K12: =E12 * (H12 / F12)^0.55 * G12 * (J12^0.8) -> 0
B13: Antalya | C13: Billboard | D13: 35793.342 | E13: =+E9*1.38 -> 17.94 | F13: 200 | G13: 1 | H13: 0 | I13: =+D13 -> 35793.342 | J13: 1 | K13: =E13 * (H13 / F13)^0.55 * G13 * (J13^0.8) -> 0
B14: Anadolu İlleri | C14: Billboard | D14: 25928.498 | E14: =+E9*1.63 -> 21.19 | F14: 200 | G14: 1 | H14: 0 | I14: =+D14 -> 25928.498 | J14: 1 | K14: =E14 * (H14 / F14)^0.55 * G14 * (J14^0.8) -> 0
B15: İstanbul | C15: Afiş Değiştiricili Megalight | D15: 21175 | E15: 3.8 | F15: 50 | G15: 1 | H15: 0 | I15: =+D15 -> 21175 | J15: 1 | K15: =E15 * (H15 / F15)^0.55 * G15 * (J15^0.8) -> 0
B16: Ankara | C16: Afiş Değiştiricili Megalight | D16: 23862.398 | E16: =+E15*1.17 -> 4.446 | F16: 50 | G16: 1 | H16: 0 | I16: =+D16 -> 23862.398 | J16: 1 | K16: =E16 * (H16 / F16)^0.55 * G16 * (J16^0.8) -> 0
B17: İzmir | C17: Afiş Değiştiricili Megalight | D17: 20533.695 | E17: =+E15*1.21 -> 4.598 | F17: 50 | G17: 1 | H17: 0 | I17: =+D17 -> 20533.695 | J17: 1 | K17: =E17 * (H17 / F17)^0.55 * G17 * (J17^0.8) -> 0
B18: Bursa | C18: Afiş Değiştiricili Megalight | D18: 13134.402 | E18: =+E15*1.27 -> 4.826 | F18: 50 | G18: 1 | H18: 0 | I18: =+D18 -> 13134.402 | J18: 1 | K18: =E18 * (H18 / F18)^0.55 * G18 * (J18^0.8) -> 0
B19: Antalya | C19: Afiş Değiştiricili Megalight | D19: 15109.224 | E19: =+E15*1.38 -> 5.244 | F19: 50 | G19: 1 | H19: 0 | I19: =+D19 -> 15109.224 | J19: 1 | K19: =E19 * (H19 / F19)^0.55 * G19 * (J19^0.8) -> 0
B20: Anadolu İlleri | C20: Afiş Değiştiricili Megalight | D20: 10945.038 | E20: =+E15*1.63 -> 6.194 | F20: 50 | G20: 1 | H20: 0 | I20: =+D20 -> 10945.038 | J20: 1 | K20: =E20 * (H20 / F20)^0.55 * G20 * (J20^0.8) -> 0
B21: İstanbul | C21: Megalight | D21: 42351 | E21: 5.2 | F21: 50 | G21: 1 | H21: 0 | I21: =+D21 -> 42351 | J21: 1 | K21: =E21 * (H21 / F21)^0.55 * G21 * (J21^0.8) -> 0
B22: Ankara | C22: Megalight | D22: 47725.922 | E22: =+$E$22*M4 -> 6.084 | F22: 50 | G22: 1 | H22: 0 | I22: =+D22 -> 47725.922 | J22: 1 | K22: =E22 * (H22 / F22)^0.55 * G22 * (J22^0.8) -> 0
B23: İzmir | C23: Megalight | D23: 41068.361 | E23: =+$E$22*M5 -> 6.292 | F23: 50 | G23: 1 | H23: 0 | I23: =+D23 -> 41068.361 | J23: 1 | K23: =E23 * (H23 / F23)^0.55 * G23 * (J23^0.8) -> 0
B24: Bursa | C24: Megalight | D24: 26269.425 | E24: =+$E$22*M6 -> 6.604 | F24: 50 | G24: 1 | H24: 0 | I24: =+D24 -> 26269.425 | J24: 1 | K24: =E24 * (H24 / F24)^0.55 * G24 * (J24^0.8) -> 0
B25: Antalya | C25: Megalight | D25: 30219.162 | E25: =+$E$22*M7 -> 7.176 | F25: 50 | G25: 1 | H25: 0 | I25: =+D25 -> 30219.162 | J25: 1 | K25: =E25 * (H25 / F25)^0.55 * G25 * (J25^0.8) -> 0
B26: Anadolu İlleri | C26: Megalight | D26: 21890.593 | E26: =+$E$22*M8 -> 8.476 | F26: 50 | G26: 1 | H26: 0 | I26: =+D26 -> 21890.593 | J26: 1 | K26: =E26 * (H26 / F26)^0.55 * G26 * (J26^0.8) -> 0 | O26: Ünite | P26: Periyod | Q26: Kullanım Süresi
B27: İstanbul | C27: Üst Geçit Alınlık | D27: 150000 | E27: 4 | F27: 5 | G27: 1 | H27: 0 | I27: =+D27 -> 150000 | J27: 1 | K27: =E27 * (H27 / F27)^0.55 * G27 * (J27^0.8) -> 0 | O27: Durak Raket CLP | P27: 1 | Q27: =+P27*7 -> 7
B28: Ankara | C28: Üst Geçit Alınlık | D28: 169037.06 | E28: =+E27*M4 -> 4.68 | F28: 5 | G28: 1 | H28: 0 | I28: =+D28 -> 169037.06 | J28: 1 | K28: =E28 * (H28 / F28)^0.55 * G28 * (J28^0.8) -> 0 | O28: Billboard | P28: 1 | Q28: =+P28*7 -> 7
B29: İzmir | C29: Üst Geçit Alınlık | D29: 145457.11 | E29: =+E28*M5 -> 5.6628 | F29: 5 | G29: 1 | H29: 0 | I29: =+D29 -> 145457.11 | J29: 1 | K29: =E29 * (H29 / F29)^0.55 * G29 * (J29^0.8) -> 0 | O29: Afiş Değiştiricili Megalight | P29: 1 | Q29: =+P29*7 -> 7
B30: Bursa | C30: Üst Geçit Alınlık | D30: 93041.81 | E30: =+E29*M6 -> 7.191756 | F30: 5 | G30: 1 | H30: 0 | I30: =+D30 -> 93041.81 | J30: 1 | K30: =E30 * (H30 / F30)^0.55 * G30 * (J30^0.8) -> 0 | O30: Megalight | P30: 1 | Q30: =+P30*7 -> 7
B31: Antalya | C31: Üst Geçit Alınlık | D31: 107031.1 | E31: =+E30*M7 -> 9.9246233 | F31: 5 | G31: 1 | H31: 0 | I31: =+D31 -> 107031.1 | J31: 1 | K31: =E31 * (H31 / F31)^0.55 * G31 * (J31^0.8) -> 0 | O31: Üst Geçit Alınlık | P31: 1 | Q31: =+P31*15 -> 15
B32: Anadolu İlleri | C32: Üst Geçit Alınlık | D32: 77532.736 | E32: =+E31*M8 -> 16.177136 | F32: 5 | G32: 1 | H32: 0 | I32: =+D32 -> 77532.736 | J32: 1 | K32: =E32 * (H32 / F32)^0.55 * G32 * (J32^0.8) -> 0 | O32: Giantboard | P32: 1 | Q32: =+P32*10 -> 10
B33: İstanbul | C33: Giantboard | D33: 100000 | E33: 3.4 | F33: 10 | G33: 1 | H33: 0 | I33: =+D33 -> 100000 | J33: 1 | K33: =E33 * (H33 / F33)^0.55 * G33 * (J33^0.8) -> 0 | O33: Elektrik Direği Banner | P33: 1 | Q33: =+P33*14 -> 14
B34: Ankara | C34: Giantboard | D34: 112691.37 | E34: =+E33*M4 -> 3.978 | F34: 10 | G34: 1 | H34: 0 | I34: =+D34 -> 112691.37 | J34: 1 | K34: =E34 * (H34 / F34)^0.55 * G34 * (J34^0.8) -> 0 | O34: Avm Dış Led Ekran | P34: 1 | Q34: =+P34*7 -> 7
B35: İzmir | C35: Giantboard | D35: 96971.407 | E35: =+$E$34*M5 -> 4.81338 | F35: 10 | G35: 1 | H35: 0 | I35: =+D35 -> 96971.407 | J35: 1 | K35: =E35 * (H35 / F35)^0.55 * G35 * (J35^0.8) -> 0 | O35: Dijital Raket | P35: 1 | Q35: =+P35*7 -> 7
B36: Bursa | C36: Giantboard | D36: 62027.873 | E36: =+$E$34*M6 -> 5.05206 | F36: 10 | G36: 1 | H36: 0 | I36: =+D36 -> 62027.873 | J36: 1 | K36: =E36 * (H36 / F36)^0.55 * G36 * (J36^0.8) -> 0 | O36: Dijital Ekran | P36: 1 | Q36: =+P36*7 -> 7
B37: Antalya | C37: Giantboard | D37: 71354.07 | E37: =+$E$34*M7 -> 5.48964 | F37: 10 | G37: 1 | H37: 0 | I37: =+D37 -> 71354.07 | J37: 1 | K37: =E37 * (H37 / F37)^0.55 * G37 * (J37^0.8) -> 0 | O37: Toplu Taşıma Ekran | P37: 1 | Q37: =+P37*7 -> 7
B38: Anadolu İlleri | C38: Giantboard | D38: 51688.491 | E38: =+$E$34*M8 -> 6.48414 | F38: 10 | G38: 1 | H38: 0 | I38: =+D38 -> 51688.491 | J38: 1 | K38: =E38 * (H38 / F38)^0.55 * G38 * (J38^0.8) -> 0 | O38: Tramvay Raket CLP | P38: 1 | Q38: =+P38*7 -> 7
B39: İstanbul | C39: Elektrik Direği Banner | D39: 13200 | E39: 21 | F39: 500 | G39: 1 | H39: 0 | I39: =+D39 -> 13200 | J39: 1 | K39: =E39 * (H39 / F39)^0.55 * G39 * (J39^0.8) -> 0 | O39: Raket CLP | P39: 1 | Q39: =+P39*7 -> 7
B40: Ankara | C40: Elektrik Direği Banner | D40: 14875.261 | E40: =+E39*M4 -> 24.57 | F40: 500 | G40: 1 | H40: 0 | I40: =+D40 -> 14875.261 | J40: 1 | K40: =E40 * (H40 / F40)^0.55 * G40 * (J40^0.8) -> 0
B41: İzmir | C41: Elektrik Direği Banner | D41: 12800.226 | E41: =+$E$40*M5 -> 29.7297 | F41: 500 | G41: 1 | H41: 0 | I41: =+D41 -> 12800.226 | J41: 1 | K41: =E41 * (H41 / F41)^0.55 * G41 * (J41^0.8) -> 0
...
